process.on('beforeExit', () => {
    console.log('El proceso va a terminar');
});

process.on('exit', () => {
    console.log('El proceso acabÃ³');
});

process.on('uncaughtException', (err, origen) => {
    console.log('Se nos ha olvidado capturar el error');
    setTimeout(() => {
        console.log('Esto viene desde las excepciones');
    }, 0);
});

funcionQueNoExiste();